[G] You're right to be curious! It might seem counterintuitive that a `catch` block, designed to handle errors, could "return normally." Let's break it down:

**Key Concepts**

* **`catch` Purpose:** The primary purpose of `catch` is to intercept errors and prevent them from crashing your program. 
* **`catch` as a Callback:** The `catch` block is essentially a callback function that executes *only* when the preceding Promise *rejects*. 
* **"Returning Normally" in `catch`:** This means that the `catch` block:
    * **Successfully executes without throwing any further errors.** 
    * **Returns a value (or a new Promise).**

**How it Works in the Example**

1. **Error in `startAsyncOperation()` or `doStageTwo()`:** If either of these functions throws an error, the Promise returned by `startAsyncOperation()` or the Promise returned by the first `.then()` (which calls `doStageTwo()`) will *reject*.

2. **`recoverFromStageTwoError()` Execution:** The `catch` block associated with the first `.then()` will now execute. 

3. **"Normal" Return from `recoverFromStageTwoError()`:**
    * **Scenario 1: Return a Value:** 
        * If `recoverFromStageTwoError()` executes its logic, handles the error gracefully (e.g., by logging an error message, attempting a fallback operation, etc.), and then returns a value, that value will be passed to the subsequent `.then()` block (which calls `doStageThree()`). The asynchronous operation continues.

    * **Scenario 2: Return a Promise:**
        * If `recoverFromStageTwoError()` itself performs an asynchronous operation (e.g., fetches data from a backup server), it can return a new Promise. If that new Promise resolves, its resolution value will be passed to `doStageThree()`. If that new Promise rejects, the error will be handled by a subsequent `.catch` block (if one exists).

**Example**

```javascript
function startAsyncOperation() {
  return new Promise((resolve, reject) => {
    // Simulate an error 
    reject(new Error("Error in startAsyncOperation")); 
  });
}

function doStageTwo() {
  // This function will not be called in this scenario 
  return Promise.resolve("Stage Two Complete"); 
}

function recoverFromStageTwoError(error) {
  console.error("Error encountered:", error); 
  return "Recovered from error!"; // Return a value after error handling
}

startAsyncOperation()
  .then(doStageTwo)
  .catch(recoverFromStageTwoError)
  .then(doStageThree) // Will receive "Recovered from error!" 

function doStageThree(data) {
  console.log("Stage Three:", data); // Output: "Stage Three: Recovered from error!"
}
```

In this simplified example:

* `startAsyncOperation()` rejects with an error.
* `recoverFromStageTwoError()` is executed, logs the error, and then returns the string "Recovered from error!".
* The third `.then()` (which calls `doStageThree()`) receives the string "Recovered from error!" as input.

**Key Takeaway:**

A "normal" return from `catch` means that the error was handled within the `catch` block, and the asynchronous operation can proceed with the subsequent `.then()` blocks using the value returned by `catch`.

I hope this clarifies how a `catch` block can "return normally" and allows the asynchronous operation to continue despite an initial error.
