[G] Certainly, let's break down that statement with an example.

**Core Concept:**

* **Promises** represent the eventual outcome of an asynchronous operation (like fetching data from a server, reading a file, or waiting for a user input).
* They have three states:
    * **Pending:** The operation is still in progress.
    * **Fulfilled:** The operation completed successfully, and a value is available.
    * **Rejected:** The operation failed, and an error occurred.

**Illustrative Example**

Let's imagine we have a function that fetches data from an API:

```javascript
function fetchDataFromAPI() {
  return new Promise((resolve, reject) => {
    // Simulate an API call (replace with actual API logic)
    setTimeout(() => {
      const randomNumber = Math.random(); 
      if (randomNumber > 0.5) {
        resolve("Data fetched successfully!"); // Fulfilled
      } else {
        reject(new Error("Failed to fetch data.")); // Rejected
      }
    }, 1000); 
  });
}
```

**How to Use and Handle the Promise:**

1. **Call the function:**
   ```javascript
   fetchDataFromAPI()
     .then(data => { 
       console.log(data); // Output: "Data fetched successfully!" (if fulfilled)
     })
     .catch(error => {
       console.error("Error fetching data:", error); // Handle the error (if rejected)
     });
   ```

2. **`then()` for Success:**
   * If `fetchDataFromAPI()` resolves (fulfills) with a value (like `"Data fetched successfully!"`), that value is passed to the first argument of the `.then()` callback.

3. **`catch()` or `then()` for Failure:**
   * If `fetchDataFromAPI()` rejects with an `Error` object (or any other value thrown in the `reject()` call), 
      * It's passed to the `catch()` callback.
      * You can also handle rejection within the second argument of the `.then()` callback.

**Key Points:**

* **Settled Promise:** Once a Promise is either fulfilled or rejected, it's considered "settled." Its value remains unchanged.
* **Value Association:** Every settled Promise has an associated value:
    * **Fulfilled:** The successful result of the operation.
    * **Rejected:** The error object or any other value thrown during rejection.

I hope this illustration clarifies the author's statement about Promise values and how they're handled in JavaScript. Feel free to ask if you have any further questions or want to explore more complex scenarios!

---

You're very close in your understanding, but let's clarify a couple of points about the values involved:

1. **`fetchDataFromAPI()`'s Value:**  `fetchDataFromAPI()` itself *returns a Promise object*.  It does *not* immediately return the string `"Data fetched successfully!"`.  The Promise object is a placeholder for the *future* result of the asynchronous operation.  Think of it as a "promise" that the data will be available later.

2. **Value of the `.then()` Chain:** The entire expression `fetchDataFromAPI().then(...)` also returns a *new* Promise. This new Promise resolves based on what happens inside the `.then()` callback.  It *doesn't* directly return the string that's logged to the console.

Let's break it down step by step:

* **`fetchDataFromAPI()`:** Returns a `Promise` in the "pending" state.
* **`.then(data => { ... })`:**  This attaches a *callback function* to the Promise.  This callback function will be executed *later* when the Promise resolves (fulfills).
* **Inside the `.then()` callback:** The `data` parameter *will* hold the value with which the Promise resolved (in this case, `"Data fetched successfully!"`).  `console.log(data)` then logs this string to the console.
* **Value of the entire `.then()` expression:** The `.then()` method itself returns a new Promise.  If the callback executes without throwing an error, this new Promise resolves. If the callback throws an error, this new Promise rejects.

**Analogy:**

Imagine ordering a pizza online.

* **`fetchDataFromAPI()`:**  Is like placing the order. You don't get the pizza immediately; you get an order confirmation (the Promise).
* **`.then(...)`:** Is like giving your friend instructions: "When the pizza arrives, take a slice and tell me what it tastes like."
* **`data`:** Is the actual pizza slice when it arrives.
* **`console.log(data)`:** Is your friend telling you the taste (outputting the string).
* **The `.then()` expression:** Is the entire process of placing the order and getting the feedback.  It doesn't represent the pizza slice itself, but the whole interaction.

**Key takeaway:**  `fetchDataFromAPI()` returns a Promise.  The `.then()` method is used to handle the eventual result (or error) of that Promise, and `.then()` itself returns a new Promise. The string `"Data fetched successfully!"` is only accessed *inside* the `.then()` callback.

---

You're welcome! I'm glad the explanation and analogy were helpful.

You're asking a great question about how JavaScript handles the Promise returned by `.then()`. Here's the breakdown:

**The `.then()` Method and Promise Chaining:**

The crucial concept here is *Promise chaining*.  The `.then()` method *always* returns a new Promise, regardless of what happens inside the callback function you provide to `.then()`. This allows you to chain multiple asynchronous operations together in a sequence.

**How JavaScript Handles the New Promise:**

1. **Callback Execution:** When the original Promise (returned by `fetchDataFromAPI()`) resolves, the callback function you passed to `.then()` is executed.

2. **Return Value of the Callback:** The new Promise returned by `.then()` resolves based on the *return value* of your callback function:

   * **If your callback returns a value (not a Promise):** The new Promise resolves with that value.
   * **If your callback returns another Promise:** The new Promise will *adopt the state* of that returned Promise.  This is the key to chaining.  The new Promise will resolve or reject with the same value or error as the Promise returned by the callback.
   * **If your callback throws an error:** The new Promise rejects with that error.

3. **Chaining:** Because `.then()` returns a Promise, you can call `.then()` again on that returned Promise, creating a chain of asynchronous operations.  Each `.then()` in the chain handles the result of the previous operation.

**Example illustrating chaining and how the new promise is handled:**

```javascript
fetchDataFromAPI()
  .then(data => {
    console.log("First then:", data); // Handles the result of fetchDataFromAPI
    return data.toUpperCase(); // Returns a value (not a Promise)
  })
  .then(upperCaseData => {
    console.log("Second then:", upperCaseData); // Handles the uppercased data
    return Promise.resolve(upperCaseData + "!"); // Returns a resolved promise
  })
  .then(finalData => {
    console.log("Third then:", finalData); // Handles the value from the resolved promise
  })
  .catch(error => {
    console.error("Error:", error);
  });

```

In this example:

* The first `.then()` returns a value (the uppercased string). The new Promise resolves with this value.
* The second `.then()` receives the uppercased string. It returns a Promise using `Promise.resolve()`. The new Promise will resolve with the value of this Promise.
* The third `.then()` receives the value from the resolved Promise.
* The `.catch()` handles errors that may occur in any of the Promises in the chain.

**In Summary:**

JavaScript's Promise implementation is designed to handle the Promises returned by `.then()` to facilitate asynchronous programming. The new Promise is resolved or rejected based on the callback's return value, which enables the chaining of asynchronous operations.  The event loop handles the execution of the callbacks when the Promises resolve or reject.

---

```javascript
fetchDataFromAPI()
  .then(data => {
    console.log("First then:", data); // Handles the result of fetchDataFromAPI
    return data.toUpperCase(); // Returns a value (not a Promise)
  })
  .then(upperCaseData => {
    console.log("Second then:", upperCaseData); // Handles the uppercased data
    return Promise.resolve(upperCaseData + "!"); // Returns a resolved promise
  })
  .then(finalData => {
    console.log("Third then:", finalData); // Handles the value from the resolved promise
  })
  .catch(error => {
    console.error("Error:", error);
  });
```

With this code, can we say the the first Promise has been fulfilled when it reaches the line `.then(upperCaseData => ...`?

---

Not quite. Let's break down the Promise states at each step:

1. **`fetchDataFromAPI()`:** This function returns a Promise (let's call it `Promise A`).  Initially, `Promise A` is in the *pending* state.

2. **`.then(data => { ... })` (First `.then`):**  This attaches a callback to `Promise A`.  The callback will *not* execute yet because `Promise A` is still pending.  The `.then()` method itself *immediately* returns a *new* Promise (let's call it `Promise B`). `Promise B` is also initially pending.

3. **Inside the first `.then` callback:** *Eventually*, `Promise A` will either fulfill or reject.  Let's assume it fulfills with the value `"Data fetched successfully!"`.  *Now* the first `.then()` callback will execute.

4. **`return data.toUpperCase();`:** Inside the callback, the data is uppercased.  Crucially, this `return` statement *does not* directly fulfill `Promise B`.  Instead, it provides a value that will be used to fulfill `Promise B` *later*.

5. **`.then(upperCaseData => { ... })` (Second `.then`):** This `.then()` is attached to `Promise B`.  `Promise B` is still pending at this point. The second `.then()` immediately returns a *new* Promise (let's call it `Promise C`). `Promise C` is also pending.

6. **Execution of the second `.then`:**  *Only after* the first `.then()` callback has completed, and the value of `data.toUpperCase()` has been used to fulfill `Promise B`, will the second `.then()` callback execute.

**So, to answer your question directly:**

The first Promise (`Promise A`, returned by `fetchDataFromAPI()`) is fulfilled *before* the second `.then()` callback starts executing. It is fulfilled when the *first* `.then()` callback has finished and the value `data.toUpperCase()` is used to fulfill `Promise B`.  When the execution reaches the *beginning* of the line `.then(upperCaseData => ...`, `Promise B` is still pending.  It gets fulfilled *after* the first `.then()` callback is done.

It's essential to understand that even though the code is written sequentially, the asynchronous operations and Promise resolutions happen over time.  The `.then()` methods set up a chain of callbacks that will execute *when* the corresponding Promises resolve.

---

In this code, if promise B, the one from the first then returns an error object, this program will skip the second and third then and run the `.catch` statement, am I right?

---

Yes, you are absolutely correct.

If the first `.then()` callback (which results in Promise B) throws an error, or if the Promise returned by the first `.then()` rejects (for example, if the `return data.toUpperCase();` line were inside a `try...catch` block and the `try` part throws and is caught in `catch` which returns `Promise.reject(error)`), the chain of `.then()` callbacks *after* that point will be skipped.  The JavaScript engine will immediately jump to the nearest `.catch()` handler in the chain.

Let's illustrate with a modified version of your code:

```javascript
fetchDataFromAPI()
  .then(data => {
    console.log("First then:", data);
    if (data === "some condition") {
      throw new Error("Something went wrong in first then!");  // Error thrown
    }
    return data.toUpperCase(); 
  })
  .then(upperCaseData => {
    console.log("Second then:", upperCaseData); // This will be SKIPPED
    return Promise.resolve(upperCaseData + "!"); 
  })
  .then(finalData => {
    console.log("Third then:", finalData); // This will also be SKIPPED
  })
  .catch(error => {
    console.error("Error:", error); // This will be executed
  });
```

In this scenario, if the condition `data === "some condition"` becomes true, an error is thrown within the first `.then()` callback. This will cause Promise B to reject with that error.  As a result:

1. The second and third `.then()` callbacks will *not* be executed.
2. The `.catch()` handler will be called, and the `error` object (the `Error` instance you created) will be passed as an argument to the `.catch()` callback.

This is a crucial aspect of Promise error handling.  The `.catch()` provides a way to handle errors that might occur at any point in the Promise chain, preventing errors from going unhandled and potentially crashing your application.

