Sure! The `try`, `catch`, `finally`, and `throw` keywords in JavaScript are used for **error handling**. They allow you to handle exceptions (errors) gracefully, preventing your program from crashing unexpectedly.

Let's break down each concept with examples.

### 1. **`try` and `catch`**
- **`try` block**: This is where you put the code that might throw an error.
- **`catch` block**: If an error occurs in the `try` block, the code in the `catch` block runs, allowing you to handle the error gracefully.

#### Example:

```javascript
try {
  // Code that might throw an error
  let result = 10 / 0; // No error here; division by zero doesn't cause an exception in JavaScript
  console.log(result);
  
  let obj = undefined;
  console.log(obj.name); // This will cause an error because 'obj' is undefined
} catch (error) {
  // Code to handle the error
  console.log("An error occurred:", error.message);
}
```

In this example:
- The first part (`10 / 0`) doesn't throw an error (division by zero in JavaScript results in `Infinity`).
- The second part (`obj.name`) throws an error because we're trying to access a property of `undefined`.
- The error is caught by the `catch` block, and the message is logged.

### 2. **`finally` Block**
- The `finally` block contains code that **always** runs, regardless of whether an error occurred or not. It's useful for cleanup actions like closing resources (e.g., closing a file, terminating a connection).

#### Example with `finally`:

```javascript
try {
  let data = "Some data";
  console.log(data);
  
  let num = 10;
  let result = num.toUpperCase(); // This will cause an error since toUpperCase is not a method of number
} catch (error) {
  console.log("Error caught:", error.message);
} finally {
  console.log("This runs no matter what, even if an error occurred.");
}
```

Output:
```
Some data
Error caught: num.toUpperCase is not a function
This runs no matter what, even if an error occurred.
```

### 3. **`throw` Statement**
- You can use `throw` to create and throw your own errors. This can be useful when you want to throw an error based on certain conditions.

#### Example with `throw`:

```javascript
function divide(a, b) {
  if (b === 0) {
    throw new Error("Division by zero is not allowed.");
  } else {
    return a / b;
  }
}

try {
  let result = divide(10, 0); // This will throw an error
  console.log(result);
} catch (error) {
  console.log("Caught an error:", error.message);
} finally {
  console.log("Division attempt finished.");
}
```

In this example:
- The `throw` statement creates a new error if `b` is `0`.
- The error is caught by the `catch` block and handled.
- The `finally` block runs regardless of whether an error was thrown.

### Summary of Each Component:
- **`try`**: Runs code that might throw an error.
- **`catch`**: Catches and handles any error thrown in the `try` block.
- **`finally`**: Runs code that executes whether an error occurred or not.
- **`throw`**: Manually throws an error, which can then be caught by `catch`.

Would you like to see more examples or a specific use case?

---

Certainly! The `throw`, `try`, `catch`, and `finally` constructs in JavaScript are used for **error handling**. They allow you to catch and manage errors that might occur in your program, preventing it from crashing unexpectedly.

### Key Concepts

1. **`throw`**: This is used to create an error intentionally. You can "throw" any value (usually an `Error` object) to indicate that something went wrong.
2. **`try`**: The block of code where you expect something might go wrong. If an error occurs here, control is passed to the `catch` block.
3. **`catch`**: This block handles the error thrown from the `try` block. It allows you to respond to the error and take some action to recover or inform the user.
4. **`finally`**: This block runs regardless of whether an error occurred or not. It is often used to clean up resources (like closing files or database connections) that were used in the `try` block.

### Example 1: Basic Error Handling with `throw`, `try`, and `catch`

```javascript
function divide(a, b) {
  if (b === 0) {
    throw new Error("Division by zero is not allowed!");
  }
  return a / b;
}

try {
  console.log(divide(10, 2));  // Output: 5
  console.log(divide(10, 0));  // Throws an error
} catch (error) {
  console.log("Error caught:", error.message);  // Output: Error caught: Division by zero is not allowed!
}
```

**Explanation:**
- In the `divide` function, we throw an error when someone tries to divide by zero.
- The `try` block tries to execute `divide(10, 0)`. When it throws an error, the program immediately jumps to the `catch` block.
- The `catch` block receives the error and prints the error message. This prevents the program from crashing.

### Example 2: Using `finally` for Cleanup

```javascript
function openFile() {
  console.log("Opening file...");
}

function closeFile() {
  console.log("Closing file...");
}

function readFile(file) {
  if (!file) {
    throw new Error("File not found!");
  }
  console.log("Reading file...");
}

try {
  openFile();
  readFile(null);  // This will throw an error because the file is null
} catch (error) {
  console.log("Error caught:", error.message);  // Output: Error caught: File not found!
} finally {
  closeFile();  // This will always run, regardless of the error
}
```

**Explanation:**
- The `try` block opens a file and tries to read it. If the file is `null`, it throws an error.
- The `catch` block catches the error and logs it.
- The `finally` block runs whether or not an error occurred, ensuring that the file is always closed properly.

### Example 3: Custom Errors

You can also create custom error objects using `throw`:

```javascript
class CustomError extends Error {
  constructor(message) {
    super(message);
    this.name = "CustomError";
  }
}

function checkAge(age) {
  if (age < 18) {
    throw new CustomError("You must be 18 or older!");
  }
  return "You are allowed!";
}

try {
  console.log(checkAge(20));  // Output: You are allowed!
  console.log(checkAge(15));  // Throws a CustomError
} catch (error) {
  if (error instanceof CustomError) {
    console.log("Custom error caught:", error.message);  // Output: Custom error caught: You must be 18 or older!
  } else {
    console.log("Unknown error:", error);
  }
}
```

**Explanation:**
- Here we define a custom error class `CustomError` that extends the built-in `Error` class.
- If the `checkAge` function is called with an age less than 18, it throws a `CustomError`.
- The `catch` block checks if the error is an instance of `CustomError` and handles it accordingly.

### Recap:

- **`throw`** is used to manually throw an error.
- **`try`** is used to wrap code where you expect an error might occur.
- **`catch`** is used to handle the error if one is thrown.
- **`finally`** runs regardless of whether an error was thrown or not, and is often used for cleanup.

You can use these constructs to manage and handle errors gracefully in your code.